Workbook

Sheet Summary
A1: Tsuji — cost overview
A2: All figures in €. Green = pulled from another sheet. Status: student self-employed (étudiant-indépendant), VAT-exempt while eligible.
A4: Prices (VAT included)
A5: Pro – monthly / annual | B5: =Assumptions!$B$10 -> 4.99 | C5: =Assumptions!$B$11 -> 49.99
A6: Max – monthly / annual | B6: =Assumptions!$B$12 -> 7.99 | C6: =Assumptions!$B$13 -> 59.99
A8: To start (one-off)
A9: Start-up costs – required items, expected | B9: ='Start-up costs'!$I$23 -> 979.327
A10: Start-up costs – including optional items (EU trademark, Mac, marketing…) | B10: ='Start-up costs'!$I$24 -> 3729.327
A12: Fixed costs per month
A13: Launch stage | B13: ='Fixed costs'!$I$24 -> 232.68245
A14: Growth stage | B14: ='Fixed costs'!$J$24 -> 355.32145
A15: Scale stage | B15: ='Fixed costs'!$K$24 -> 736.5767
A16: First 12 months before any revenue (start-up + 12 × Launch) | B16: ='Start-up costs'!$I$23+12*'Fixed costs'!$I$24 -> 3771.5164
A18: Per subscriber, per month (after VAT, fees, LLM, infrastructure)
A19: Pro – contribution margin (blended monthly/annual) | B19: ='Unit economics'!$O$11 -> 1.9976421
A20: Max – contribution margin (blended) | B20: ='Unit economics'!$O$12 -> 3.4058055
A21: All payers – contribution margin | B21: ='Unit economics'!$O$13 -> 2.2536718
A22: All payers – margin, worst-case LLM | B22: ='Unit economics'!$R$13 -> -0.044162172
A23: One free user – variable cost (infrastructure and AI) | B23: ='Unit economics'!$C$29 -> 0.030812
A25: Break-even at the Launch stage (conservative, with VAT on web sales)
A26: Paying users needed | B26: ='Unit economics'!$D$23 -> 100
A27: Active users needed (at the assumed conversion) | B27: ='Unit economics'!$E$23 -> 1801
A29: Projection (from the 'Projection' sheet)
A30: Active users | B30: =Projection!B5 -> 100 | C30: =Projection!C5 -> 500 | D30: =Projection!D5 -> 1000 | E30: =Projection!E5 -> 2500 | F30: =Projection!F5 -> 5000 | G30: =Projection!G5 -> 10000 | H30: =Projection!H5 -> 25000 | I30: =Projection!I5 -> 50000
A31: Net revenue / month | B31: =Projection!B18 -> 19.815322 | C31: =Projection!C18 -> 96.969656 | D31: =Projection!D18 -> 191.41595 | E31: =Projection!E18 -> 476.86179 | F31: =Projection!F18 -> 954.13999 | G31: =Projection!G18 -> 1905.3402 | H31: =Projection!H18 -> 4426.6797 | I31: =Projection!I18 -> 8850.4196
A32: Total costs / month | B32: =Projection!B29 -> 237.56145 | C32: =Projection!C29 -> 256.53716 | D32: =Projection!D29 -> 280.12172 | E32: =Projection!E29 -> 474.0547 | F32: =Projection!F29 -> 592.5178 | G32: =Projection!G29 -> 829.71415 | H32: =Projection!H29 -> 1922.5584 | I32: =Projection!I29 -> 3108.5402
A33: Social contributions / month | B33: =Projection!B34 -> 0 | C33: =Projection!C34 -> 0 | D33: =Projection!D34 -> 0 | E33: =Projection!E34 -> 0 | F33: =Projection!F34 -> 0 | G33: =Projection!G34 -> 72.099741 | H33: =Projection!H34 -> 513.34485 | I33: =Projection!I34 -> 1177.0853
A34: Result after social contributions / month | B34: =Projection!B35 -> -217.74613 | C34: =Projection!C35 -> -159.5675 | D34: =Projection!D35 -> -88.705769 | E34: =Projection!E35 -> 2.8070893 | F34: =Projection!F35 -> 361.62219 | G34: =Projection!G35 -> 1003.5263 | H34: =Projection!H35 -> 1990.7764 | I34: =Projection!I35 -> 4564.7941
A35: VAT exemption applies? (1 = yes) | B35: =Projection!B23 -> 1 | C35: =Projection!C23 -> 1 | D35: =Projection!D23 -> 1 | E35: =Projection!E23 -> 1 | F35: =Projection!F23 -> 1 | G35: =Projection!G23 -> 1 | H35: =Projection!H23 -> 0 | I35: =Projection!I23 -> 0
A36: Still within the student status? | B36: =Projection!B37 -> yes | C36: =Projection!C37 -> yes | D36: =Projection!D37 -> yes | E36: =Projection!E37 -> yes | F36: =Projection!F37 -> yes | G36: =Projection!G37 -> yes | H36: =Projection!H37 -> no: full-time rates | I36: =Projection!I37 -> no: full-time rates
A37: Cost per active user / month | B37: =Projection!B40 -> 2.3756145 | C37: =Projection!C40 -> 0.51307432 | D37: =Projection!D40 -> 0.28012172 | E37: =Projection!E40 -> 0.18962188 | F37: =Projection!F40 -> 0.11850356 | G37: =Projection!G40 -> 0.082971415 | H37: =Projection!H40 -> 0.076902338 | I37: =Projection!I40 -> 0.062170804
A38: Cost per paying user / month | B38: =Projection!B41 -> 39.593575 | C38: =Projection!C41 -> 9.1620414 | D38: =Projection!D41 -> 5.0931222 | E38: =Projection!E41 -> 3.435179 | F38: =Projection!F41 -> 2.1546102 | G38: =Projection!G41 -> 1.5085712 | H38: =Projection!H41 -> 1.3982243 | I38: =Projection!I41 -> 1.1303783
A40: Where we are, and the end-2026 goal
A41: Active users today (early access) | B41: =Assumptions!$B$59 -> 25
A42: Active users needed to break even (Launch stage) | B42: ='Unit economics'!$E$23 -> 1801
A43: … growth needed from today | B43: =IF(OR(B41=0,NOT(ISNUMBER(B42))),0,B42/B41) -> 72.04
A44: Days left to the target date | B44: =MAX(0,Assumptions!$B$60-TODAY()) -> 66
A45: Active users to add per day to get there | B45: =IF(OR(B44=0,NOT(ISNUMBER(B42))),0,(B42-B41)/B44) -> 26.909091

Sheet Assumptions
A1: Assumptions
A2: Blue = input you can change · yellow = key assumption to check · every other sheet reads from here.
A4: Parameter | B4: Value | C4: Unit | D4: Source / note
A5: General
A6: Exchange rate USD → EUR | B6: 0.86 | C6: € per $ | D6: Most providers bill in USD. Set to the current rate.
A7: VAT rate on consumer sales | B7: 0.21 | C7: % | D7: Belgium 21%. Buyers elsewhere in the EU pay their country's rate through the OSS (FR 20%, DE 19%...). Prices are VAT-inclusive.
A8: VAT you pay on services bought abroad, and can't deduct | B8: 0.21 | C8: % | D8: Under the small-business VAT exemption you can't deduct VAT. Services from outside Belgium (Render, Vercel, Supabase, Google AI, Apple...) are taxed through the reverse charge at 21% and cost 21% more. Set to 0% once you register for VAT normally. Check this with your accountant.
A9: Prices (VAT included) – see the 'Pricing' sheet
A10: Pro – monthly | B10: 4.99 | C10: € / month | D10: Owner's decision, 26 Oct 2026 (new monetisation strategy). Previous proposal €8.99; first grid €8.
A11: Pro – annual | B11: 49.99 | C11: € / year | D11: Owner's decision, 26 Oct 2026. Previous proposal €59.99. Saves 17% against 12 × monthly ('Pricing').
A12: Max – monthly | B12: 7.99 | C12: € / month | D12: Owner's decision, 26 Oct 2026. Previous proposal €14.99.
A13: Max – annual | B13: 59.99 | C13: € / year | D13: Owner's decision, 26 Oct 2026. Previous proposal €99.99. Only €10 a year above Pro annual ('Pricing').
A14: Who pays, and how
A15: Share of active users on Pro | B15: 0.045 | C15: % of MAU | D15: Freemium language apps typically convert 2–8% of active users. Replace with real data after launch.
A16: Share of active users on Max | B16: 0.01 | C16: % of MAU | D16: Max is sold mainly as an upgrade when a Pro user reaches a limit. With Max annual only €10 above Pro annual, more payers may pick Max: re-check with real data.
A17: Share of Pro payers on the annual plan | B17: 0.7 | C17: % of Pro payers | D17: The goal: most Pro buyers choose the annual plan (pre-selected, '€5 a month', trial on annual only).
A18: Share of Max payers on the annual plan | B18: 0.45 | C18: % of Max payers | D18: Upgrades from Pro annual go to annual; upgrades from Pro monthly go to monthly.
A19: Share bought through the App Store / Google Play | B19: 0.6 | C19: % of payers | D19: The rest is bought on the web (Stripe). Selling the annual plan on the landing page avoids the commission.
A20: Payment fees
A21: App Store / Google Play commission | B21: 0.15 | C21: % of price excl. VAT | D21: 15% under the Small Business Programs (< $1M/yr) and on every subscription after its first year; 30% otherwise. Stores collect and remit VAT for you.
A22: Stripe card fee (EEA cards) | B22: 0.015 | C22: % of charge | D22: Stripe Belgium standard EEA cards: 1.5% + €0.25.
A23: Stripe fixed fee per charge | B23: 0.25 | C23: € / charge | D23: Paid on every monthly renewal, once a year on annual plans.
A24: Stripe Billing (subscriptions) | B24: 0.007 | C24: % of charge | D24: Stripe Billing pay-as-you-go.
A25: Small-business VAT exemption (franchise regime)
A26: Use the VAT exemption while you're eligible (Y/N) | B26: Y | C26: Y / N | D26: Web buyers are then charged no VAT and you keep the whole price. The stores still apply VAT (they are the seller in-app).
A27: Annual turnover limit for the exemption | B27: 25000 | C27: € / year | D27: Belgian small-business exemption limit.
A28: Limit for web sales to consumers in other EU countries | B28: 10000 | C28: € / year | D28: Above this, buyers abroad pay their own country's VAT (e.g. 20% in France) even if you're exempt in Belgium. Tsuji is French-first, so this limit comes first.
A29: Share of web buyers outside Belgium | B29: 0.8 | C29: % of web sales | D29: Assumption: mostly French-speaking buyers in France.
A30: Variable cost per user per month
A31: LLM cost – Pro user, expected | B31: 0.27 | C31: $ / month | D31: scripts/llm_cost_model.py --fleet: Gemini 3.1 Flash-Lite, 70% light / 25% typical / 5% heavy, with caching. The free Explain button is included (phrase analysis, mostly cached).
A32: LLM cost – Pro user, worst case | B32: ='AI worst case'!$L$26 -> 2.4 | C32: $ / month | D32: From 'AI worst case' (full-price tier): every AI allowance used to the full, every day.
A33: LLM cost – Max user, expected | B33: 0.44 | C33: $ / month | D33: llm_cost_model.py 'typical' user: Max buyers use the app more.
A34: LLM cost – Max user, worst case | B34: ='AI worst case'!$M$26 -> 3 | C34: $ / month | D34: From 'AI worst case' (full-price tier): every AI allowance used to the full, every day.
A35: Variable infrastructure – free user | B35: 0.01 | C35: € / month | D35: Database, auth and bandwidth beyond what the fixed plans include.
A36: Variable infrastructure – paying user | B36: 0.02 | C36: € / month | D36: More audio, practice logs and analyser history.
A37: Stages (which fixed-cost column applies)
A38: Growth stage starts at | B38: 2000 | C38: active users | D38: Bigger Render/Supabase plans, paid e-mail. See 'Fixed costs'.
A39: Scale stage starts at | B39: 20000 | C39: active users
A40: Social contributions – student self-employed (étudiant-indépendant), 2026
A41: No contributions up to | B41: 8687.04 | C41: € net profit / year | D41: Below this taxable profit you owe nothing (2026, UCM / Liantis / Partena).
...

Sheet Pricing
A1: Pricing: pushing the annual Pro plan, with Max as the upgrade
A2: Old prices are your first grid; full prices come from Assumptions (change them there); regional prices are at the bottom.
A4: Plan | B4: Billing | C4: Previous proposal (€) | D4: Full price, tier 1 (€) | E4: Per month (€) | F4: Saving vs monthly | G4: Change vs previous | H4: Store price point?
A5: Pro | B5: Monthly | C5: 8.99 | D5: =Assumptions!$B$10 -> 4.99 | E5: =D5/1 -> 4.99 | G5: =D5/C5-1 -> -0.44493882 | H5: =IF(MOD(ROUND(D5*100,0),100)=99,"yes","round to .99") -> yes
A6: Pro | B6: Annual | C6: 59.99 | D6: =Assumptions!$B$11 -> 49.99 | E6: =D6/12 -> 4.1658333 | F6: =1-D6/(12*D5) -> 0.16516366 | G6: =D6/C6-1 -> -0.16669445 | H6: =IF(MOD(ROUND(D6*100,0),100)=99,"yes","round to .99") -> yes
A7: Max | B7: Monthly | C7: 14.99 | D7: =Assumptions!$B$12 -> 7.99 | E7: =D7/1 -> 7.99 | G7: =D7/C7-1 -> -0.46697799 | H7: =IF(MOD(ROUND(D7*100,0),100)=99,"yes","round to .99") -> yes
A8: Max | B8: Annual | C8: 99.99 | D8: =Assumptions!$B$13 -> 59.99 | E8: =D8/12 -> 4.9991667 | F8: =1-D8/(12*D7) -> 0.37432207 | G8: =D8/C8-1 -> -0.40004 | H8: =IF(MOD(ROUND(D8*100,0),100)=99,"yes","round to .99") -> yes
A10: Upgrade to Max
A11: From Pro annual to Max annual, per year | D11: =D8-D6 -> 10 | E11: =IF(D11<0.5*D6,"Max annual is close to Pro annual: most annual buyers will take Max","") -> Max annual is close to Pro annual: most annual buyers will take Max
A12: … per month | D12: =(D8-D6)/12 -> 0.83333333
A13: From Pro monthly to Max monthly, per month | D13: =D7-D5 -> 3
A14: Charge only the difference for the months left (proration): the stores do it automatically for upgrades within a subscription group, and so does Stripe.
A16: Competitors (list prices, USD)
A17: App | B17: What it covers | C17: Monthly ($) | D17: Annual ($) | E17: Lifetime ($) | H17: Source
A18: WaniKani | B18: Kanji and vocabulary only | C18: 9 | D18: 89 | E18: 299 | H18: wanilog.com, 2026
A19: Bunpro | B19: Grammar only | C19: 5 | D19: — | E19: 150 | H19: languavibe.com, May 2026
A20: Renshuu Pro | B20: Vocab, kanji, grammar | C20: 6.99 | D20: 49.99 | E20: 109.99 | H20: App Store listing, 2026
A21: WaniKani + Bunpro | B21: What Tsuji Pro replaces | C21: 14 | D21: — | E21: — | H21: Sum of the two monthly prices
A23: Why these prices
A24: 1 | B24: Pro €4.99 / €49.99 (owner's decision, Oct 2026): a low entry price, the strategy's 'learn well for little'. Annual saves only 17% against 12 × monthly: a weak reason to commit for a year.
A25: 2 | B25: Max €7.99 / €59.99: annual saves 37% and costs only €10 a year more than Pro annual. Side by side, Max annual is the obvious pick and Pro annual a decoy. Either that is the intent (more per payer, thinner worst case) or Pro annual moves (e.g. €39.99, −33%).
A26: 3 | B26: Both plans hold their worst case only through the global AI ceiling a day ('AI worst case'): the per-feature caps alone add up to more than either price carries.
A27: 4 | B27: Max 'unlimited' covers everything paid in credits. The AI features keep fair-use caps and a ceiling, published as such.
A28: 5 | B28: All four prices are standard App Store / Google Play price points (x.99).
A29: 6 | B29: 7-day free trial on the annual plans only, and the founder offer (below) for early-access members.
A30: 7 | B30: Sell the annual plans on the web too (landing page, Stripe). In-app you keep about 70% of the price; on the web, VAT-exempt, about 97%. The founder offer holds its worst case only on the web.
A31: 8 | B31: Re-check after launch: conversion, the annual share, the Pro/Max split, how many reach a cap or the ceiling. Change them in Assumptions.
A33: Regional prices, by purchasing power
A34: Tier | B34: Countries (examples) | C34: Share of payers | D34: Pro price & AI multiplier | E34: Max price & AI multiplier | F34: Pro monthly (€) | G34: Pro annual (€) | H34: Max monthly (€) | I34: Max annual (€) | J34: Pro monthly: worst-case margin/mo (€) | K34: Pro annual: worst-case margin/mo (€) | L34: Max monthly: worst-case margin/mo (€) | M34: Max annual: worst-case margin/mo (€) | N34: Every plan covers its worst case?
A35: 1 – Full price | B35: Belgium, France, Switzerland, Luxembourg, Germany, Netherlands, Nordics, UK, US, Canada, Australia, Japan | C35: 0.7 | D35: 1 | E35: 1 | F35: =MAX(0.99,CEILING(Assumptions!$B$10*D35,1)-0.01) -> 4.99 | G35: =MAX(0.99,CEILING(Assumptions!$B$11*D35,1)-0.01) -> 49.99 | H35: =MAX(0.99,CEILING(Assumptions!$B$12*E35,1)-0.01) -> 7.99 | I35: =MAX(0.99,CEILING(Assumptions!$B$13*E35,1)-0.01) -> 59.99 | J35: =MIN(F35/1/(1+Assumptions!$B$7)*(1-Assumptions!$B$21),(F35/(1+Assumptions!$B$7)-(F35*(Assumptions!$B$22+Assumptions!$B$24)+Assumptions!$B$23))/1)-'AI worst case'!$F$33-Assumptions!$B$36 -> 0.9879319 | K35: =MIN(G35/12/(1+Assumptions!$B$7)*(1-Assumptions!$B$21),(G35/(1+Assumptions!$B$7)-(G35*(Assumptions!$B$22+Assumptions!$B$24)+Assumptions!$B$23))/12)-'AI worst case'!$F$33-Assumptions!$B$36 -> 0.40897185 | L35: =MIN(H35/1/(1+Assumptions!$B$7)*(1-Assumptions!$B$21),(H35/(1+Assumptions!$B$7)-(H35*(Assumptions!$B$22+Assumptions!$B$24)+Assumptions!$B$23))/1)-'AI worst case'!$G$33-Assumptions!$B$36 -> 2.4710099 | M35: =MIN(I35/12/(1+Assumptions!$B$7)*(1-Assumptions!$B$21),(I35/(1+Assumptions!$B$7)-(I35*(Assumptions!$B$22+Assumptions!$B$24)+Assumptions!$B$23))/12)-'AI worst case'!$G$33-Assumptions!$B$36 -> 0.37001129 | N35: =IF(MIN(J35:M35)>='AI worst case'!$B$10,"yes","NO: raise the price or lower the allowance") -> yes
A36: 2 – Reduced | B36: Spain, Italy, Portugal, Greece, Poland, Czechia, the Baltics, Korea, Taiwan | C36: 0.15 | D36: 0.75 | E36: 0.75 | F36: =MAX(0.99,CEILING(Assumptions!$B$10*D36,1)-0.01) -> 3.99 | G36: =MAX(0.99,CEILING(Assumptions!$B$11*D36,1)-0.01) -> 37.99 | H36: =MAX(0.99,CEILING(Assumptions!$B$12*E36,1)-0.01) -> 5.99 | I36: =MAX(0.99,CEILING(Assumptions!$B$13*E36,1)-0.01) -> 44.99 | J36: =MIN(F36/1/(1+Assumptions!$B$7)*(1-Assumptions!$B$21),(F36/(1+Assumptions!$B$7)-(F36*(Assumptions!$B$22+Assumptions!$B$24)+Assumptions!$B$23))/1)-'AI worst case'!$F$34-Assumptions!$B$36 -> 0.93998736 | K36: =MIN(G36/12/(1+Assumptions!$B$7)*(1-Assumptions!$B$21),(G36/(1+Assumptions!$B$7)-(G36*(Assumptions!$B$22+Assumptions!$B$24)+Assumptions!$B$23))/12)-'AI worst case'!$F$34-Assumptions!$B$36 -> 0.36102731 | L36: =MIN(H36/1/(1+Assumptions!$B$7)*(1-Assumptions!$B$21),(H36/(1+Assumptions!$B$7)-(H36*(Assumptions!$B$22+Assumptions!$B$24)+Assumptions!$B$23))/1)-'AI worst case'!$G$34-Assumptions!$B$36 -> 1.8465012 | M36: =MIN(I36/12/(1+Assumptions!$B$7)*(1-Assumptions!$B$21),(I36/(1+Assumptions!$B$7)-(I36*(Assumptions!$B$22+Assumptions!$B$24)+Assumptions!$B$23))/12)-'AI worst case'!$G$34-Assumptions!$B$36 -> 0.27236212 | N36: =IF(MIN(J36:M36)>='AI worst case'!$B$10,"yes","NO: raise the price or lower the allowance") -> yes
A37: 3 – Low | B37: Morocco, Algeria, Tunisia, Turkey, Romania, Brazil, Mexico, Southeast Asia | C37: 0.1 | D37: 0.55 | E37: 0.55 | F37: =MAX(0.99,CEILING(Assumptions!$B$10*D37,1)-0.01) -> 2.99 | G37: =MAX(0.99,CEILING(Assumptions!$B$11*D37,1)-0.01) -> 27.99 | H37: =MAX(0.99,CEILING(Assumptions!$B$12*E37,1)-0.01) -> 4.99 | I37: =MAX(0.99,CEILING(Assumptions!$B$13*E37,1)-0.01) -> 32.99 | J37: =MIN(F37/1/(1+Assumptions!$B$7)*(1-Assumptions!$B$21),(F37/(1+Assumptions!$B$7)-(F37*(Assumptions!$B$22+Assumptions!$B$24)+Assumptions!$B$23))/1)-'AI worst case'!$F$35-Assumptions!$B$36 -> 0.73301573 | K37: =MIN(G37/12/(1+Assumptions!$B$7)*(1-Assumptions!$B$21),(G37/(1+Assumptions!$B$7)-(G37*(Assumptions!$B$22+Assumptions!$B$24)+Assumptions!$B$23))/12)-'AI worst case'!$F$35-Assumptions!$B$36 -> 0.27113556 | L37: =MIN(H37/1/(1+Assumptions!$B$7)*(1-Assumptions!$B$21),(H37/(1+Assumptions!$B$7)-(H37*(Assumptions!$B$22+Assumptions!$B$24)+Assumptions!$B$23))/1)-'AI worst case'!$G$35-Assumptions!$B$36 -> 1.7683819 | M37: =MIN(I37/12/(1+Assumptions!$B$7)*(1-Assumptions!$B$21),(I37/(1+Assumptions!$B$7)-(I37*(Assumptions!$B$22+Assumptions!$B$24)+Assumptions!$B$23))/12)-'AI worst case'!$G$35-Assumptions!$B$36 -> 0.19424278 | N37: =IF(MIN(J37:M37)>='AI worst case'!$B$10,"yes","NO: raise the price or lower the allowance") -> yes
A38: 4 – Lowest | B38: Senegal, Côte d'Ivoire, Cameroon and French-speaking Africa, India, Egypt | C38: 0.05 | D38: 0.45 | E38: 0.45 | F38: =MAX(0.99,CEILING(Assumptions!$B$10*D38,1)-0.01) -> 2.99 | G38: =MAX(0.99,CEILING(Assumptions!$B$11*D38,1)-0.01) -> 22.99 | H38: =MAX(0.99,CEILING(Assumptions!$B$12*E38,1)-0.01) -> 3.99 | I38: =MAX(0.99,CEILING(Assumptions!$B$13*E38,1)-0.01) -> 26.99 | J38: =MIN(F38/1/(1+Assumptions!$B$7)*(1-Assumptions!$B$21),(F38/(1+Assumptions!$B$7)-(F38*(Assumptions!$B$22+Assumptions!$B$24)+Assumptions!$B$23))/1)-'AI worst case'!$F$36-Assumptions!$B$36 -> 1.1374423 | K38: =MIN(G38/12/(1+Assumptions!$B$7)*(1-Assumptions!$B$21),(G38/(1+Assumptions!$B$7)-(G38*(Assumptions!$B$22+Assumptions!$B$24)+Assumptions!$B$23))/12)-'AI worst case'!$F$36-Assumptions!$B$36 -> 0.38286243 | L38: =MIN(H38/1/(1+Assumptions!$B$7)*(1-Assumptions!$B$21),(H38/(1+Assumptions!$B$7)-(H38*(Assumptions!$B$22+Assumptions!$B$24)+Assumptions!$B$23))/1)-'AI worst case'!$G$36-Assumptions!$B$36 -> 1.3780826 | M38: =MIN(I38/12/(1+Assumptions!$B$7)*(1-Assumptions!$B$21),(I38/(1+Assumptions!$B$7)-(I38*(Assumptions!$B$22+Assumptions!$B$24)+Assumptions!$B$23))/12)-'AI worst case'!$G$36-Assumptions!$B$36 -> 0.15518311 | N38: =IF(MIN(J38:M38)>='AI worst case'!$B$10,"yes","NO: raise the price or lower the allowance") -> yes
A39: Average price paid (index) | C39: =SUM(C35:C38) -> 1 | D39: =IF(C39=0,1,SUMPRODUCT(C35:C38,D35:D38)/C39) -> 0.89 | E39: =IF(C39=0,1,SUMPRODUCT(C35:C38,E35:E38)/C39) -> 0.89
A41: The rule: in every tier, even a subscriber using every AI allowance to the full every day must still bring in more than they cost. The margins above are that case, in the channel that keeps least (in-app or web).
A42: The multiplier sets both the price and the AI caps and ceiling in that tier: pay 45% of the price, get 45% of the AI. Reviews, the dictionary and the credits are the same everywhere; they cost almost nothing.
A43: The global AI ceiling is what lets tier 4 hold: without it the per-feature caps alone would cost more than a tier-4 plan brings in.
A44: Which price applies: the store account's country in-app (Apple and Google set prices per country); on the web, the country of the card (Stripe), so a VPN doesn't unlock a cheaper price.
A45: Outside the EU the stores add the local sales tax (e.g. India 18%). The margins use the EU rate as an approximation.
A46: 'Unit economics' and 'Projection' use the average indexes, so revenue already reflects regional prices. The shares of payers must add up to 100%.
...

Sheet Credit shop
A1: Credit shop: packs priced so that the subscriptions stay the better deal
A2: Blue = input · prices VAT included · every reward is fixed: nothing random is ever sold or paid for with bought credits (Belgium treats paid loot boxes as gambling).
A4: The credit economy (owner's decisions, Oct 2026; figures to tune with early-access data)
A5: Free: credits refilled a day | B5: 60
A6: Free: refill limit (the refill stops there; earned and bought credits go above it) | B6: 90
A7: Pro: credits refilled a day | B7: 120
A8: Pro: refill limit | B8: 200
A9: Due review on Free (credits) | B9: 1
A10: Due review on Pro and Max (credits) | B10: 0
A11: Practice exercise (2 to 5 by mode; average) | B11: 3
A12: Due reviews a day of a steady Pro learner (for the comparison below) | B12: 60
A14: Packs: the bigger the pack, the bigger the bonus
A15: Pack | B15: Credits | C15: Price (€) | D15: € per 100 credits | E15: Bonus vs the smallest pack | F15: Share of packs sold | G15: You keep in-app (€) | H15: You keep on the web, VAT-exempt (€)
A16: S | B16: 100 | C16: 0.99 | D16: =IF(B16=0,0,C16/B16*100) -> 0.99 | E16: =IF(C16=0,0,B16/(C16/$C$16*$B$16)-1) -> 0 | F16: 0.35 | G16: =C16/(1+Assumptions!$B$7)*(1-Assumptions!$B$21) -> 0.69545455 | H16: =C16-(C16*(Assumptions!$B$22+Assumptions!$B$24)+Assumptions!$B$23) -> 0.71822
A17: M | B17: 330 | C17: 2.99 | D17: =IF(B17=0,0,C17/B17*100) -> 0.90606061 | E17: =IF(C17=0,0,B17/(C17/$C$16*$B$16)-1) -> 0.09264214 | F17: 0.35 | G17: =C17/(1+Assumptions!$B$7)*(1-Assumptions!$B$21) -> 2.1004132 | H17: =C17-(C17*(Assumptions!$B$22+Assumptions!$B$24)+Assumptions!$B$23) -> 2.67422
A18: L | B18: 600 | C18: 4.99 | D18: =IF(B18=0,0,C18/B18*100) -> 0.83166667 | E18: =IF(C18=0,0,B18/(C18/$C$16*$B$16)-1) -> 0.19038076 | F18: 0.2 | G18: =C18/(1+Assumptions!$B$7)*(1-Assumptions!$B$21) -> 3.5053719 | H18: =C18-(C18*(Assumptions!$B$22+Assumptions!$B$24)+Assumptions!$B$23) -> 4.63022
A19: XL | B19: 1300 | C19: 9.99 | D19: =IF(B19=0,0,C19/B19*100) -> 0.76846154 | E19: =IF(C19=0,0,B19/(C19/$C$16*$B$16)-1) -> 0.28828829 | F19: 0.1 | G19: =C19/(1+Assumptions!$B$7)*(1-Assumptions!$B$21) -> 7.0177686 | H19: =C19-(C19*(Assumptions!$B$22+Assumptions!$B$24)+Assumptions!$B$23) -> 9.52022
A20: Mix check (must be 100%) | F20: =SUM(F16:F19) -> 1
A21: Average pack sold | C21: =SUMPRODUCT(C16:C19,F16:F19) -> 3.39 | G21: =SUMPRODUCT(G16:G19,F16:F19) -> 2.381405 | H21: =SUMPRODUCT(H16:H19,F16:F19) -> 3.06542
A22: Kept per pack sold, blended by channel (€) | G22: =Assumptions!$B$58*G21+(1-Assumptions!$B$58)*H21 -> 2.4498065
A24: Do the subscriptions stay the better deal?
A25: Extra credits a month Pro refills over Free | B25: =(B7-B5)*30 -> 1800
A26: Due reviews a month Pro rides free (credits Free would pay) | B26: =B12*30*(B9-B10) -> 1800
A27: A Pro month, in credits | B27: =B25+B26 -> 3600
A28: Those credits bought in packs, at the best rate (€) | B28: =B27*MIN(D16:D19)/100 -> 27.664615
A29: … as a multiple of Pro monthly | B29: =IF(Assumptions!$B$10=0,0,B28/Assumptions!$B$10) -> 5.5440111
A30: Largest limited-time promotion (extra credits on a pack) | B30: 0.5
A31: … multiple of Pro monthly during that promotion | B31: =IF(Assumptions!$B$10=0,0,B28/(1+B30)/Assumptions!$B$10) -> 3.6960074
A32: Target: packs cost at least this multiple of Pro monthly | B32: 1.5
A33: Pro stays the better deal, even during a promotion? | B33: =IF(MIN(B29,B31)>=B32,"yes","NO: raise the pack prices or shrink the bonus") -> yes
A35: Bigger packs carry a bigger bonus (owner's decision). A limited-time promotion adds credits to a pack; it never takes a price off the store's price points.
A36: Show the € price beside every credit amount and every price in credits, never pressure a buy (no fake countdown), and size the packs so nobody is left with an unusable remainder: the EU consumer authorities' principles on in-game virtual currencies (March 2025).
A37: Bought and earned credits never expire (owner's decision) and survive a change of plan. They never raise a plan's AI caps. The shop is hidden from Max (unlimited).

Sheet AI worst case
A1: AI worst case: a user who uses every AI allowance to the full, every day
A2: Caps at the full price (tier 1); cheaper tiers scale them by their multiplier ('Pricing'). Each plan has per-feature caps AND one global ceiling a day, whatever the mix: the worst case is the lower of the two. Only this sheet decides whether a price can lose money.
A4: Model prices (Gemini 3.1 Flash-Lite, the primary)
A5: Input price | B5: 0.25 | C5: $ per 1M tokens | D5: docs/llm-commercial-plan.md. No batch discount in the worst case.
A6: Output price | B6: 1.5 | C6: $ per 1M tokens
A7: Share of input served from the provider's cache | B7: 0.6 | C7: %
A8: Cached input billed at | B8: 0.1 | C8: of the full price
A9: Days in a month | B9: 30 | C9: days
A10: Minimum margin per subscriber per month, worst case | B10: 0.1 | C10: € | D10: 0 = break even; a little above leaves room for error.
A12: Feature (one unit) | B12: Calls per unit | C12: Input tokens per call | D12: Output tokens per call | E12: Cost per unit ($) | F12: Cap per | G12: Free cap | H12: Pro cap | I12: Max cap | J12: Units a month per cap | K12: Free ($/month) | L12: Pro ($/month) | M12: Max ($/month) | N12: What the code does today
A13: New mock-exam paper generated | B13: 35 | C13: 1300 | D13: 2000 | E13: =B13*(C13*$B$5*(1-$B$7+$B$7*$B$8)+D13*$B$6)/1000000 -> 0.1102325 | F13: month | G13: 0 | H13: 2 | I13: 4 | J13: =IF(F13="day",$B$9,1) -> 1 | K13: =G13*$E13*$J13 -> 0 | L13: =H13*$E13*$J13 -> 0.220465 | M13: =I13*$E13*$J13 -> 0.44093 | N13: Papers already in the pool stay open to all (credits). TODAY: 5 new papers a day (EXAM_PAPERS_DAILY_LIMIT).
A14: New comprehension text generated | B14: 1.3 | C14: 2700 | D14: 3000 | E14: =B14*(C14*$B$5*(1-$B$7+$B$7*$B$8)+D14*$B$6)/1000000 -> 0.00625365 | F14: day | G14: 0 | H14: 1 | I14: 2 | J14: =IF(F14="day",$B$9,1) -> 30 | K14: =G14*$E14*$J14 -> 0 | L14: =H14*$E14*$J14 -> 0.1876095 | M14: =I14*$E14*$J14 -> 0.375219 | N14: Texts from the pool are free to serve (30–60 hand-written seeds a level). TODAY: 10 a day (COMPREHENSION_DAILY_LIMIT).
A15: Composition review (one sentence) | B15: 1 | C15: 900 | D15: 400 | E15: =B15*(C15*$B$5*(1-$B$7+$B$7*$B$8)+D15*$B$6)/1000000 -> 0.0007035 | F15: day | G15: 3 | H15: 15 | I15: 25 | J15: =IF(F15="day",$B$9,1) -> 30 | K15: =G15*$E15*$J15 -> 0.063315 | L15: =H15*$E15*$J15 -> 0.316575 | M15: =I15*$E15*$J15 -> 0.527625 | N15: TODAY: 30 a day (COMPOSITION_DAILY_LIMIT).
A16: Translation review (one sentence) | B16: 1 | C16: 600 | D16: 400 | E16: =B16*(C16*$B$5*(1-$B$7+$B$7*$B$8)+D16*$B$6)/1000000 -> 0.000669 | F16: day | G16: 3 | H16: 15 | I16: 25 | J16: =IF(F16="day",$B$9,1) -> 30 | K16: =G16*$E16*$J16 -> 0.06021 | L16: =H16*$E16*$J16 -> 0.30105 | M16: =I16*$E16*$J16 -> 0.50175 | N16: TODAY: 60 a day (TRANSLATION_DAILY_LIMIT).
A17: Conversation: one line spoken (会話) | B17: 1 | C17: 1700 | D17: 450 | E17: =B17*(C17*$B$5*(1-$B$7+$B$7*$B$8)+D17*$B$6)/1000000 -> 0.0008705 | F17: day | G17: 6 | H17: 18 | I17: 30 | J17: =IF(F17="day",$B$9,1) -> 30 | K17: =G17*$E17*$J17 -> 0.15669 | L17: =H17*$E17*$J17 -> 0.47007 | M17: =I17*$E17*$J17 -> 0.78345 | N17: One call answers and reviews the line. TODAY: 80 a day (CONVERSATION_DAILY_LIMIT).
A18: Conversation: translated reply reviewed | B18: 1 | C18: 1100 | D18: 400 | E18: =B18*(C18*$B$5*(1-$B$7+$B$7*$B$8)+D18*$B$6)/1000000 -> 0.0007265 | F18: day | G18: 2 | H18: 8 | I18: 15 | J18: =IF(F18="day",$B$9,1) -> 30 | K18: =G18*$E18*$J18 -> 0.04359 | L18: =H18*$E18*$J18 -> 0.17436 | M18: =I18*$E18*$J18 -> 0.326925 | N18: TODAY: 60 a day (CONVERSATION_REVIEW_DAILY_LIMIT).
A19: Chatbot question (問) | B19: 1 | C19: 1400 | D19: 120 | E19: =B19*(C19*$B$5*(1-$B$7+$B$7*$B$8)+D19*$B$6)/1000000 -> 0.000341 | F19: day | G19: 5 | H19: 20 | I19: 40 | J19: =IF(F19="day",$B$9,1) -> 30 | K19: =G19*$E19*$J19 -> 0.05115 | L19: =H19*$E19*$J19 -> 0.2046 | M19: =I19*$E19*$J19 -> 0.4092 | N19: TODAY: 40 a day (ASK_DAILY_LIMIT).
A20: Explain / analyser (a sentence not in the cache) | B20: 1 | C20: 400 | D20: 500 | E20: =B20*(C20*$B$5*(1-$B$7+$B$7*$B$8)+D20*$B$6)/1000000 -> 0.000796 | F20: day | G20: 5 | H20: 15 | I20: 30 | J20: =IF(F20="day",$B$9,1) -> 30 | K20: =G20*$E20*$J20 -> 0.1194 | L20: =H20*$E20*$J20 -> 0.3582 | M20: =I20*$E20*$J20 -> 0.7164 | N20: Cached sentences stay unlimited. TODAY: 150 a day (DEEP_DAILY_LIMIT).
A21: Photo reading (OCR) | B21: 1 | C21: 1400 | D21: 400 | E21: =B21*(C21*$B$5*(1-$B$7+$B$7*$B$8)+D21*$B$6)/1000000 -> 0.000761 | F21: day | G21: 1 | H21: 5 | I21: 15 | J21: =IF(F21="day",$B$9,1) -> 30 | K21: =G21*$E21*$J21 -> 0.02283 | L21: =H21*$E21*$J21 -> 0.11415 | M21: =I21*$E21*$J21 -> 0.34245 | N21: TODAY: 20 a day (OCR_DAILY_LIMIT).
A22: Video / passage: a block of 20 lines translated | B22: 1 | C22: 900 | D22: 700 | E22: =B22*(C22*$B$5*(1-$B$7+$B$7*$B$8)+D22*$B$6)/1000000 -> 0.0011535 | F22: day | G22: 2 | H22: 8 | I22: 20 | J22: =IF(F22="day",$B$9,1) -> 30 | K22: =G22*$E22*$J22 -> 0.06921 | L22: =H22*$E22*$J22 -> 0.27684 | M22: =I22*$E22*$J22 -> 0.6921 | N22: A video of ~150 lines is ~8 blocks. TODAY: 60 a day (LINE_TRANSLATION_DAILY_LIMIT).
A23: Song lyrics sorted | B23: 1 | C23: 1400 | D23: 900 | E23: =B23*(C23*$B$5*(1-$B$7+$B$7*$B$8)+D23*$B$6)/1000000 -> 0.001511 | F23: day | G23: 0 | H23: 2 | I23: 5 | J23: =IF(F23="day",$B$9,1) -> 30 | K23: =G23*$E23*$J23 -> 0 | L23: =H23*$E23*$J23 -> 0.09066 | M23: =I23*$E23*$J23 -> 0.22665 | N23: TODAY: 20 a day (LYRICS_SORT_DAILY_LIMIT).
A24: Sum of the per-feature caps ($/month) | K24: =SUM(K13:K23) -> 0.586395 | L24: =SUM(L13:L23) -> 2.7145795 | M24: =SUM(M13:M23) -> 5.342699
A25: Global AI ceiling a day, whatever the mix ($) | G25: 0.01 | H25: 0.08 | I25: 0.1 | K25: =G25*$B$9 -> 0.3 | L25: =H25*$B$9 -> 2.4 | M25: =I25*$B$9 -> 3 | N25: Proposal. Counted in $ of model cost a learner causes in a day, from the usage log: it never shows, it only stops an abuser.
A26: Worst case per month, full price ($) | K26: =MIN(K24,K25) -> 0.3 | L26: =MIN(L24,L25) -> 2.4 | M26: =MIN(M24,M25) -> 3
A27: … in €, with the non-deductible VAT on services bought abroad | K27: =K26*Assumptions!$B$6*(1+Assumptions!$B$8) -> 0.31218 | L27: =L26*Assumptions!$B$6*(1+Assumptions!$B$8) -> 2.49744 | M27: =M26*Assumptions!$B$6*(1+Assumptions!$B$8) -> 3.1218
A28: The ceiling, as composition reviews in one day | G28: =IF($E$15=0,0,G25/$E$15) -> 14.214641 | H28: =IF($E$15=0,0,H25/$E$15) -> 113.71713 | I28: =IF($E$15=0,0,I25/$E$15) -> 142.14641
A29: The ceiling, as chatbot questions in one day | G29: =IF($E$19=0,0,G25/$E$19) -> 29.325513 | H29: =IF($E$19=0,0,H25/$E$19) -> 234.60411 | I29: =IF($E$19=0,0,I25/$E$19) -> 293.25513
A31: By regional tier (caps and ceiling scaled by the tier's multiplier)
A32: Tier | B32: Pro multiplier | C32: Max multiplier | D32: Pro worst case ($/mo) | E32: Max worst case ($/mo) | F32: Pro worst case (€/mo) | G32: Max worst case (€/mo)
A33: =Pricing!A35 -> 1 – Full price | B33: =Pricing!D35 -> 1 | C33: =Pricing!E35 -> 1 | D33: =MIN(SUMPRODUCT(ROUNDDOWN($H$13:$H$23*B33,0),$E$13:$E$23,$J$13:$J$23),$H$25*B33*$B$9) -> 2.4 | E33: =MIN(SUMPRODUCT(ROUNDDOWN($I$13:$I$23*C33,0),$E$13:$E$23,$J$13:$J$23),$I$25*C33*$B$9) -> 3 | F33: =D33*Assumptions!$B$6*(1+Assumptions!$B$8) -> 2.49744 | G33: =E33*Assumptions!$B$6*(1+Assumptions!$B$8) -> 3.1218
A34: =Pricing!A36 -> 2 – Reduced | B34: =Pricing!D36 -> 0.75 | C34: =Pricing!E36 -> 0.75 | D34: =MIN(SUMPRODUCT(ROUNDDOWN($H$13:$H$23*B34,0),$E$13:$E$23,$J$13:$J$23),$H$25*B34*$B$9) -> 1.7710025 | E34: =MIN(SUMPRODUCT(ROUNDDOWN($I$13:$I$23*C34,0),$E$13:$E$23,$J$13:$J$23),$I$25*C34*$B$9) -> 2.25 | F34: =D34*Assumptions!$B$6*(1+Assumptions!$B$8) -> 1.8429052 | G34: =E34*Assumptions!$B$6*(1+Assumptions!$B$8) -> 2.34135
A35: =Pricing!A37 -> 3 – Low | B35: =Pricing!D37 -> 0.55 | C35: =Pricing!E37 -> 0.55 | D35: =MIN(SUMPRODUCT(ROUNDDOWN($H$13:$H$23*B35,0),$E$13:$E$23,$J$13:$J$23),$H$25*B35*$B$9) -> 1.2948275 | E35: =MIN(SUMPRODUCT(ROUNDDOWN($I$13:$I$23*C35,0),$E$13:$E$23,$J$13:$J$23),$I$25*C35*$B$9) -> 1.65 | F35: =D35*Assumptions!$B$6*(1+Assumptions!$B$8) -> 1.3473975 | G35: =E35*Assumptions!$B$6*(1+Assumptions!$B$8) -> 1.71699
A36: =Pricing!A38 -> 4 – Lowest | B36: =Pricing!D38 -> 0.45 | C36: =Pricing!E38 -> 0.45 | D36: =MIN(SUMPRODUCT(ROUNDDOWN($H$13:$H$23*B36,0),$E$13:$E$23,$J$13:$J$23),$H$25*B36*$B$9) -> 0.90618 | E36: =MIN(SUMPRODUCT(ROUNDDOWN($I$13:$I$23*C36,0),$E$13:$E$23,$J$13:$J$23),$I$25*C36*$B$9) -> 1.35 | F36: =D36*Assumptions!$B$6*(1+Assumptions!$B$8) -> 0.94297091 | G36: =E36*Assumptions!$B$6*(1+Assumptions!$B$8) -> 1.40481
A38: Expected use is far below this (Assumptions: ≈ $0.27 Pro, $0.44 Max, $0.02 Free). This sheet is a floor for prices, not a forecast.
A39: Credits bought in packs never raise a plan's AI caps: a Free learner who buys credits keeps Free's caps. PvP scores, corrections and the solo games are assumed to call no model (pre-generated content).

Sheet Start-up costs
A1: One-off costs to start
A2: Include = Y counts in the totals · amounts in the currency named · the € columns are calculated, adding the non-deductible VAT on services bought abroad (Assumptions).
A4: Item | B4: Category | C4: Include (Y/N) | D4: Currency | E4: Low | F4: Expected | G4: High | H4: Low (€) | I4: Expected (€) | J4: High (€) | K4: Note / source
A5: Registration in the BCE (enterprise number) via a guichet d'entreprises | B5: Legal & admin | C5: Y | D5: EUR | E5: 111.5 | F5: 111.5 | G5: 111.5 | H5: =E5*IF($D5="USD",Assumptions!$B$6*(1+Assumptions!$B$8),1) -> 111.5 | I5: =F5*IF($D5="USD",Assumptions!$B$6*(1+Assumptions!$B$8),1) -> 111.5 | J5: =G5*IF($D5="USD",Assumptions!$B$6*(1+Assumptions!$B$8),1) -> 111.5 | K5: 2026 official fee, the same at every guichet. VAT activation through the guichet is included. Ask for the small-business VAT exemption (franchise) at the same time.
A6: Student self-employed status (étudiant-indépendant) | B6: Legal & admin | C6: Y | D6: EUR | E6: 0 | F6: 0 | G6: 0 | H6: =E6*IF($D6="USD",Assumptions!$B$6*(1+Assumptions!$B$8),1) -> 0 | I6: =F6*IF($D6="USD",Assumptions!$B$6*(1+Assumptions!$B$8),1) -> 0 | J6: =G6*IF($D6="USD",Assumptions!$B$6*(1+Assumptions!$B$8),1) -> 0 | K6: Free: request it from your social insurance fund, with proof of enrolment every academic year (18–25 years old, at least 27 credits).
A7: VAT number activation | B7: Legal & admin | C7: Y | D7: EUR | E7: 0 | F7: 0 | G7: 0 | H7: =E7*IF($D7="USD",Assumptions!$B$6*(1+Assumptions!$B$8),1) -> 0 | I7: =F7*IF($D7="USD",Assumptions!$B$6*(1+Assumptions!$B$8),1) -> 0 | J7: =G7*IF($D7="USD",Assumptions!$B$6*(1+Assumptions!$B$8),1) -> 0 | K7: Included in the BCE fee. Under the exemption you file no periodic VAT returns, only the special return for services bought abroad.
A8: Joining a social insurance fund (caisse d'assurances sociales) | B8: Legal & admin | C8: Y | D8: EUR | E8: 0 | F8: 0 | G8: 0 | H8: =E8*IF($D8="USD",Assumptions!$B$6*(1+Assumptions!$B$8),1) -> 0 | I8: =F8*IF($D8="USD",Assumptions!$B$6*(1+Assumptions!$B$8),1) -> 0 | J8: =G8*IF($D8="USD",Assumptions!$B$6*(1+Assumptions!$B$8),1) -> 0 | K8: Free to join. The contributions are in 'Assumptions' and 'Projection'.
A9: Setting up a company (SRL) instead of working in your own name | B9: Legal & admin | C9: N | D9: EUR | E9: 1000 | F9: 1400 | G9: 2000 | H9: =E9*IF($D9="USD",Assumptions!$B$6*(1+Assumptions!$B$8),1) -> 1000 | I9: =F9*IF($D9="USD",Assumptions!$B$6*(1+Assumptions!$B$8),1) -> 1400 | J9: =G9*IF($D9="USD",Assumptions!$B$6*(1+Assumptions!$B$8),1) -> 2000 | K9: Not compatible with the student self-employed status as a sole trader. Only for later, once profit passes the student limit.
A10: Benelux trademark 'Tsuji' (BOIP), classes 9 (software) + 41 (education) | B10: Legal & admin | C10: Y | D10: EUR | E10: 271 | F10: 271 | G10: 271 | H10: =E10*IF($D10="USD",Assumptions!$B$6*(1+Assumptions!$B$8),1) -> 271 | I10: =F10*IF($D10="USD",Assumptions!$B$6*(1+Assumptions!$B$8),1) -> 271 | J10: =G10*IF($D10="USD",Assumptions!$B$6*(1+Assumptions!$B$8),1) -> 271 | K10: BOIP: €244 for the first class, €27 for each extra class. Valid 10 years. Check the fee on boip.int before filing.
A11: EU trademark (EUIPO), classes 9 + 41 | B11: Legal & admin | C11: N | D11: EUR | E11: 900 | F11: 900 | G11: 900 | H11: =E11*IF($D11="USD",Assumptions!$B$6*(1+Assumptions!$B$8),1) -> 900 | I11: =F11*IF($D11="USD",Assumptions!$B$6*(1+Assumptions!$B$8),1) -> 900 | J11: =G11*IF($D11="USD",Assumptions!$B$6*(1+Assumptions!$B$8),1) -> 900 | K11: €850 + €50 for the second class. Covers the whole EU instead of Benelux only.
A12: Trademark clearance search / IP attorney | B12: Legal & admin | C12: N | D12: EUR | E12: 0 | F12: 0 | G12: 500 | H12: =E12*IF($D12="USD",Assumptions!$B$6*(1+Assumptions!$B$8),1) -> 0 | I12: =F12*IF($D12="USD",Assumptions!$B$6*(1+Assumptions!$B$8),1) -> 0 | J12: =G12*IF($D12="USD",Assumptions!$B$6*(1+Assumptions!$B$8),1) -> 500 | K12: 'Tsuji' is a common Japanese surname. Check nobody already holds it in classes 9/41.
A13: Legal texts: terms of use, terms of sale, subscription and withdrawal terms | B13: Legal & admin | C13: Y | D13: EUR | E13: 0 | F13: 400 | G13: 1500 | H13: =E13*IF($D13="USD",Assumptions!$B$6*(1+Assumptions!$B$8),1) -> 0 | I13: =F13*IF($D13="USD",Assumptions!$B$6*(1+Assumptions!$B$8),1) -> 400 | J13: =G13*IF($D13="USD",Assumptions!$B$6*(1+Assumptions!$B$8),1) -> 1500 | K13: EU consumer law: the 14-day withdrawal right, auto-renewal terms. public/privacy.html already exists.
A14: Accountant onboarding | B14: Legal & admin | C14: Y | D14: EUR | E14: 0 | F14: 150 | G14: 300 | H14: =E14*IF($D14="USD",Assumptions!$B$6*(1+Assumptions!$B$8),1) -> 0 | I14: =F14*IF($D14="USD",Assumptions!$B$6*(1+Assumptions!$B$8),1) -> 150 | J14: =G14*IF($D14="USD",Assumptions!$B$6*(1+Assumptions!$B$8),1) -> 300 | K14: Some offices charge a set-up fee.
A15: Google Play developer registration | B15: Stores & tech | C15: Y | D15: USD | E15: 25 | F15: 25 | G15: 25 | H15: =E15*IF($D15="USD",Assumptions!$B$6*(1+Assumptions!$B$8),1) -> 26.015 | I15: =F15*IF($D15="USD",Assumptions!$B$6*(1+Assumptions!$B$8),1) -> 26.015 | J15: =G15*IF($D15="USD",Assumptions!$B$6*(1+Assumptions!$B$8),1) -> 26.015 | K15: Paid once. (The Apple fee is yearly, so it is in 'Fixed costs'.)
A16: Mac for building and uploading the iOS app | B16: Stores & tech | C16: N | D16: EUR | E16: 0 | F16: 0 | G16: 700 | H16: =E16*IF($D16="USD",Assumptions!$B$6*(1+Assumptions!$B$8),1) -> 0 | I16: =F16*IF($D16="USD",Assumptions!$B$6*(1+Assumptions!$B$8),1) -> 0 | J16: =G16*IF($D16="USD",Assumptions!$B$6*(1+Assumptions!$B$8),1) -> 700 | K16: Only if you don't own one. Cloud macOS build services are the alternative.
A17: Test devices (a used iPhone and Android phone) | B17: Stores & tech | C17: N | D17: EUR | E17: 0 | F17: 150 | G17: 400 | H17: =E17*IF($D17="USD",Assumptions!$B$6*(1+Assumptions!$B$8),1) -> 0 | I17: =F17*IF($D17="USD",Assumptions!$B$6*(1+Assumptions!$B$8),1) -> 150 | J17: =G17*IF($D17="USD",Assumptions!$B$6*(1+Assumptions!$B$8),1) -> 400
A18: First fill of the LLM pools (exam papers, comprehension, phrase cache) | B18: Stores & tech | C18: Y | D18: USD | E18: 10 | F18: 20 | G18: 40 | H18: =E18*IF($D18="USD",Assumptions!$B$6*(1+Assumptions!$B$8),1) -> 10.406 | I18: =F18*IF($D18="USD",Assumptions!$B$6*(1+Assumptions!$B$8),1) -> 20.812 | J18: =G18*IF($D18="USD",Assumptions!$B$6*(1+Assumptions!$B$8),1) -> 41.624 | K18: 10 papers for each of the 15 exam ids ≈ $17 (≈ $0.11 a paper), comprehension pool ≈ $2, phrase cache ≈ $0.20. A deep paper pool means the new-paper allowance is almost never reached.
A19: Payment integration (Stripe / RevenueCat) | B19: Stores & tech | C19: Y | D19: EUR | E19: 0 | F19: 0 | G19: 0 | H19: =E19*IF($D19="USD",Assumptions!$B$6*(1+Assumptions!$B$8),1) -> 0 | I19: =F19*IF($D19="USD",Assumptions!$B$6*(1+Assumptions!$B$8),1) -> 0 | J19: =G19*IF($D19="USD",Assumptions!$B$6*(1+Assumptions!$B$8),1) -> 0 | K19: No set-up fee. The work is development time (HAS_STORE is still false).
A20: Voice licences (VOICEVOX Nemo, kana voice) | B20: Stores & tech | C20: Y | D20: EUR | E20: 0 | F20: 0 | G20: 0 | H20: =E20*IF($D20="USD",Assumptions!$B$6*(1+Assumptions!$B$8),1) -> 0 | I20: =F20*IF($D20="USD",Assumptions!$B$6*(1+Assumptions!$B$8),1) -> 0 | J20: =G20*IF($D20="USD",Assumptions!$B$6*(1+Assumptions!$B$8),1) -> 0 | K20: Free, but you must credit 'VOICEVOX Nemo' (already done), and generated audio must never be used for machine learning.
A21: Launch marketing (ads, store screenshots, video) | B21: Marketing | C21: N | D21: EUR | E21: 0 | F21: 300 | G21: 1500 | H21: =E21*IF($D21="USD",Assumptions!$B$6*(1+Assumptions!$B$8),1) -> 0 | I21: =F21*IF($D21="USD",Assumptions!$B$6*(1+Assumptions!$B$8),1) -> 300 | J21: =G21*IF($D21="USD",Assumptions!$B$6*(1+Assumptions!$B$8),1) -> 1500 | K21: Optional. The landing page and its footage are self-made.
A23: Total – included items (Y) | H23: =SUMIFS(H5:H21,$C$5:$C$21,"Y") -> 418.921 | I23: =SUMIFS(I5:I21,$C$5:$C$21,"Y") -> 979.327 | J23: =SUMIFS(J5:J21,$C$5:$C$21,"Y") -> 2250.139
A24: Total – every item, including optional | H24: =SUM(H5:H21) -> 2318.921 | I24: =SUM(I5:I21) -> 3729.327 | J24: =SUM(J5:J21) -> 8250.139

Sheet Fixed costs
A1: Recurring fixed costs, by stage
A2: Amounts as billed (currency and period named) · € per month is calculated, adding the non-deductible VAT on services bought abroad · Include = Y counts in the totals.
A4: Item | B4: Category | C4: Include (Y/N) | D4: Currency | E4: Billed per | F4: Launch | G4: Growth | H4: Scale | I4: Launch (€/mo) | J4: Growth (€/mo) | K4: Scale (€/mo) | L4: Note / source
A5: Render – backend (FastAPI web service) | B5: Hosting | C5: Y | D5: USD | E5: month | F5: 7 | G5: 25 | H5: 85 | I5: =F5*IF($D5="USD",Assumptions!$B$6*(1+Assumptions!$B$8),1)/IF($E5="year",12,1) -> 7.2842 | J5: =G5*IF($D5="USD",Assumptions!$B$6*(1+Assumptions!$B$8),1)/IF($E5="year",12,1) -> 26.015 | K5: =H5*IF($D5="USD",Assumptions!$B$6*(1+Assumptions!$B$8),1)/IF($E5="year",12,1) -> 88.451 | L5: render.yaml: plan 'starter' (512 MB, 0.5 CPU). Standard $25 (2 GB, 1 CPU), Pro $85 (4 GB, 2 CPU).
A6: Render – persistent disk (exam and dictation audio) | B6: Hosting | C6: Y | D6: USD | E6: month | F6: 0.25 | G6: 1.25 | H6: 5 | I6: =F6*IF($D6="USD",Assumptions!$B$6*(1+Assumptions!$B$8),1)/IF($E6="year",12,1) -> 0.26015 | J6: =G6*IF($D6="USD",Assumptions!$B$6*(1+Assumptions!$B$8),1)/IF($E6="year",12,1) -> 1.30075 | K6: =H6*IF($D6="USD",Assumptions!$B$6*(1+Assumptions!$B$8),1)/IF($E6="year",12,1) -> 5.203 | L6: $0.25 per GB per month. render.yaml: 1 GB → 5 GB → 20 GB.
A7: Render – VOICEVOX Nemo voice engine (private service) | B7: Hosting | C7: Y | D7: USD | E7: month | F7: 7 | G7: 25 | H7: 25 | I7: =F7*IF($D7="USD",Assumptions!$B$6*(1+Assumptions!$B$8),1)/IF($E7="year",12,1) -> 7.2842 | J7: =G7*IF($D7="USD",Assumptions!$B$6*(1+Assumptions!$B$8),1)/IF($E7="year",12,1) -> 26.015 | K7: =H7*IF($D7="USD",Assumptions!$B$6*(1+Assumptions!$B$8),1)/IF($E7="year",12,1) -> 26.015 | L7: ADR 0019: Starter holds it (343 MB) but slowly; Standard halves the first-play wait.
A8: Render – workspace plan | B8: Hosting | C8: Y | D8: USD | E8: month | F8: 0 | G8: 0 | H8: 19 | I8: =F8*IF($D8="USD",Assumptions!$B$6*(1+Assumptions!$B$8),1)/IF($E8="year",12,1) -> 0 | J8: =G8*IF($D8="USD",Assumptions!$B$6*(1+Assumptions!$B$8),1)/IF($E8="year",12,1) -> 0 | K8: =H8*IF($D8="USD",Assumptions!$B$6*(1+Assumptions!$B$8),1)/IF($E8="year",12,1) -> 19.7714 | L8: Hobby is free. Professional ($19 per member) for autoscaling and a second instance.
A9: Vercel – frontend and /api proxy | B9: Hosting | C9: Y | D9: USD | E9: month | F9: 20 | G9: 20 | H9: 20 | I9: =F9*IF($D9="USD",Assumptions!$B$6*(1+Assumptions!$B$8),1)/IF($E9="year",12,1) -> 20.812 | J9: =G9*IF($D9="USD",Assumptions!$B$6*(1+Assumptions!$B$8),1)/IF($E9="year",12,1) -> 20.812 | K9: =H9*IF($D9="USD",Assumptions!$B$6*(1+Assumptions!$B$8),1)/IF($E9="year",12,1) -> 20.812 | L9: The free Hobby plan is non-commercial only. A paid app needs Pro ($20 per member; 1 TB of traffic included).
A10: Supabase – Postgres database + authentication | B10: Hosting | C10: Y | D10: USD | E10: month | F10: 25 | G10: 30 | H10: 75 | I10: =F10*IF($D10="USD",Assumptions!$B$6*(1+Assumptions!$B$8),1)/IF($E10="year",12,1) -> 26.015 | J10: =G10*IF($D10="USD",Assumptions!$B$6*(1+Assumptions!$B$8),1)/IF($E10="year",12,1) -> 31.218 | K10: =H10*IF($D10="USD",Assumptions!$B$6*(1+Assumptions!$B$8),1)/IF($E10="year",12,1) -> 78.045 | L10: The free plan pauses after 7 idle days and has no backups. Pro $25 includes 100k MAU, 8 GB of disk and Micro compute; Small compute +$5, Medium +$50.
A11: Transactional e-mail for auth (sign-up confirmation, password reset) | B11: Hosting | C11: Y | D11: USD | E11: month | F11: 0 | G11: 20 | H11: 20 | I11: =F11*IF($D11="USD",Assumptions!$B$6*(1+Assumptions!$B$8),1)/IF($E11="year",12,1) -> 0 | J11: =G11*IF($D11="USD",Assumptions!$B$6*(1+Assumptions!$B$8),1)/IF($E11="year",12,1) -> 20.812 | K11: =H11*IF($D11="USD",Assumptions!$B$6*(1+Assumptions!$B$8),1)/IF($E11="year",12,1) -> 20.812 | L11: Supabase's built-in mail is for testing only (a few mails an hour). E.g. Resend: free for 3,000 a month (100 a day), $20 for 50,000.
A12: Error tracking and uptime monitoring | B12: Hosting | C12: Y | D12: USD | E12: month | F12: 0 | G12: 0 | H12: 26 | I12: =F12*IF($D12="USD",Assumptions!$B$6*(1+Assumptions!$B$8),1)/IF($E12="year",12,1) -> 0 | J12: =G12*IF($D12="USD",Assumptions!$B$6*(1+Assumptions!$B$8),1)/IF($E12="year",12,1) -> 0 | K12: =H12*IF($D12="USD",Assumptions!$B$6*(1+Assumptions!$B$8),1)/IF($E12="year",12,1) -> 27.0556 | L12: Free plans are enough early. Sentry Team $26.
A13: LLM – offline jobs (refilling the comprehension pool, new exam papers) | B13: AI | C13: Y | D13: USD | E13: month | F13: 2 | G13: 5 | H13: 10 | I13: =F13*IF($D13="USD",Assumptions!$B$6*(1+Assumptions!$B$8),1)/IF($E13="year",12,1) -> 2.0812 | J13: =G13*IF($D13="USD",Assumptions!$B$6*(1+Assumptions!$B$8),1)/IF($E13="year",12,1) -> 5.203 | K13: =H13*IF($D13="USD",Assumptions!$B$6*(1+Assumptions!$B$8),1)/IF($E13="year",12,1) -> 10.406 | L13: Not tied to any one user. §5.4: a full prewarm ≈ $4. Per-user LLM spend is in 'Unit economics'.
A14: Rotating residential proxy (fetching YouTube subtitles) | B14: AI | C14: N | D14: USD | E14: month | F14: 3.5 | G14: 7 | H14: 14 | I14: =F14*IF($D14="USD",Assumptions!$B$6*(1+Assumptions!$B$8),1)/IF($E14="year",12,1) -> 3.6421 | J14: =G14*IF($D14="USD",Assumptions!$B$6*(1+Assumptions!$B$8),1)/IF($E14="year",12,1) -> 7.2842 | K14: =H14*IF($D14="USD",Assumptions!$B$6*(1+Assumptions!$B$8),1)/IF($E14="year",12,1) -> 14.5684 | L14: Only if you switch the YouTube-link feature on (it is off today). Webshare Rotating Residential $3.50 per GB, ≈ 2,500 analyses per GB.
A15: Domain name (e.g. tsuji.app) | B15: Web | C15: Y | D15: USD | E15: year | F15: 15 | G15: 15 | H15: 15 | I15: =F15*IF($D15="USD",Assumptions!$B$6*(1+Assumptions!$B$8),1)/IF($E15="year",12,1) -> 1.30075 | J15: =G15*IF($D15="USD",Assumptions!$B$6*(1+Assumptions!$B$8),1)/IF($E15="year",12,1) -> 1.30075 | K15: =H15*IF($D15="USD",Assumptions!$B$6*(1+Assumptions!$B$8),1)/IF($E15="year",12,1) -> 1.30075 | L15: The app still runs on japanese-learner-seven.vercel.app. A .app domain costs ≈ $14–20 a year.
A16: Contact mailbox (contact@…) | B16: Web | C16: Y | D16: EUR | E16: month | F16: 0 | G16: 0 | H16: 7 | I16: =F16*IF($D16="USD",Assumptions!$B$6*(1+Assumptions!$B$8),1)/IF($E16="year",12,1) -> 0 | J16: =G16*IF($D16="USD",Assumptions!$B$6*(1+Assumptions!$B$8),1)/IF($E16="year",12,1) -> 0 | K16: =H16*IF($D16="USD",Assumptions!$B$6*(1+Assumptions!$B$8),1)/IF($E16="year",12,1) -> 7 | L16: Free forwarding at first (e.g. Cloudflare Email Routing), then a real mailbox.
... A22: Paid acquisition / ads | B22: Marketing | C22: N | D22: EUR | E22: month | F22: 0 | G22: 200 | H22: 1000 | I22: =F22*IF($D22="USD",Assumptions!$B$6*(1+Assumptions!$B$8),1)/IF($E22="year",12,1) -> 0 | J22: =G22*IF($D22="USD",Assumptions!$B$6*(1+Assumptions!$B$8),1)/IF($E22="year",12,1) -> 200 | K22: =H22*IF($D22="USD",Assumptions!$B$6*(1+Assumptions!$B$8),1)/IF($E22="year",12,1) -> 1000 | L22: Optional. Set it once you know your cost per install.
A24: Total per month – included items (Y) | I24: =SUMIFS(I5:I22,$C$5:$C$22,"Y") -> 232.68245 | J24: =SUMIFS(J5:J22,$C$5:$C$22,"Y") -> 355.32145 | K24: =SUMIFS(K5:K22,$C$5:$C$22,"Y") -> 736.5767
A25: Total per year – included items (Y) | I25: =I24*12 -> 2792.1894 | J25: =J24*12 -> 4263.8574 | K25: =K24*12 -> 8838.9204
A26: Total per month – every item, including optional | I26: =SUM(I5:I22) -> 236.32455 | J26: =SUM(J5:J22) -> 587.60565 | K26: =SUM(K5:K22) -> 1791.1451
A28: Stages: Launch below the Growth threshold, Growth from it, Scale from the Scale threshold (see Assumptions).

Sheet Unit economics
A1: Unit economics: what one subscriber brings in and costs, per month
A2: Prices are averaged over the regional tiers (Pricing) · annual plans are spread over 12 months · in-app and web sales are blended by the channel mix · VAT shown as if charged on the web too (the exemption is added back in 'Projection'). · annual plans carry the founder discount for the share of payers in their founder year (Assumptions) · the 7-day trial's cost is spread over the year it buys.
A4: Plan | B4: Billing | C4: Average price paid incl. VAT (€) | D4: Months covered | E4: Charges per month | F4: Gross per month (€) | G4: VAT (€) | H4: Net of VAT (€) | I4: Store commission if sold in-app (€) | J4: Stripe fees if sold on web (€) | K4: Payment cost, blended (€) | L4: Net revenue (€) | M4: LLM, expected (€) | N4: Infrastructure (€) | O4: Contribution margin (€) | P4: Margin % of gross | Q4: LLM, worst case (€) | R4: Margin, worst case (€) | S4: Discount vs monthly
A5: Pro | B5: Monthly | C5: =Assumptions!$B$10*Pricing!$D$39 -> 4.4411 | D5: 1 | E5: =1/D5 -> 1 | F5: =C5/D5 -> 4.4411 | G5: =F5-H5 -> 0.77076942 | H5: =F5/(1+Assumptions!$B$7) -> 3.6703306 | I5: =H5*Assumptions!$B$21 -> 0.55054959 | J5: =F5*(Assumptions!$B$22+Assumptions!$B$24)+Assumptions!$B$23*E5 -> 0.3477042 | K5: =Assumptions!$B$19*I5+(1-Assumptions!$B$19)*J5 -> 0.46941143 | L5: =H5-K5 -> 3.2009191 | M5: =Assumptions!$B$31*Assumptions!$B$6*(1+Assumptions!$B$8) -> 0.280962 | N5: =Assumptions!$B$36 -> 0.02 | O5: =L5-M5-N5 -> 2.8999571 | P5: =IF(F5=0,0,O5/F5) -> 0.65298173 | Q5: =Assumptions!$B$32*Assumptions!$B$6*(1+Assumptions!$B$8) -> 2.49744 | R5: =L5-Q5-N5 -> 0.68347915
A6: Pro | B6: Annual | C6: =Assumptions!$B$11*Pricing!$D$39*(1-Assumptions!$B$53*Assumptions!$B$52) -> 31.14377 | D6: 12 | E6: =1/D6 -> 0.083333333 | F6: =C6/D6 -> 2.5953142 | G6: =F6-H6 -> 0.45042643 | H6: =F6/(1+Assumptions!$B$7) -> 2.1448877 | I6: =H6*Assumptions!$B$21 -> 0.32173316 | J6: =F6*(Assumptions!$B$22+Assumptions!$B$24)+Assumptions!$B$23*E6 -> 0.077930245 | K6: =Assumptions!$B$19*I6+(1-Assumptions!$B$19)*J6 -> 0.22421199 | L6: =H6-K6 -> 1.9206757 | M6: =Assumptions!$B$31*Assumptions!$B$6*(1+Assumptions!$B$8) -> 0.280962 | N6: =Assumptions!$B$36 -> 0.02 | O6: =L6-M6-N6-$C$35 -> 1.6109357 | P6: =IF(F6=0,0,O6/F6) -> 0.62070932 | Q6: =Assumptions!$B$32*Assumptions!$B$6*(1+Assumptions!$B$8) -> 2.49744 | R6: =L6-Q6-N6-$C$35 -> -0.60554231 | S6: =1-C6/(12*C5) -> 0.41561456
A7: Max | B7: Monthly | C7: =Assumptions!$B$12*Pricing!$E$39 -> 7.1111 | D7: 1 | E7: =1/D7 -> 1 | F7: =C7/D7 -> 7.1111 | G7: =F7-H7 -> 1.2341579 | H7: =F7/(1+Assumptions!$B$7) -> 5.8769421 | I7: =H7*Assumptions!$B$21 -> 0.88154132 | J7: =F7*(Assumptions!$B$22+Assumptions!$B$24)+Assumptions!$B$23*E7 -> 0.4064442 | K7: =Assumptions!$B$19*I7+(1-Assumptions!$B$19)*J7 -> 0.69150247 | L7: =H7-K7 -> 5.1854397 | M7: =Assumptions!$B$33*Assumptions!$B$6*(1+Assumptions!$B$8) -> 0.457864 | N7: =Assumptions!$B$36 -> 0.02 | O7: =L7-M7-N7 -> 4.7075757 | P7: =IF(F7=0,0,O7/F7) -> 0.66200386 | Q7: =Assumptions!$B$34*Assumptions!$B$6*(1+Assumptions!$B$8) -> 3.1218 | R7: =L7-Q7-N7 -> 2.0436397
A8: Max | B8: Annual | C8: =Assumptions!$B$13*Pricing!$E$39*(1-Assumptions!$B$53*Assumptions!$B$52) -> 37.37377 | D8: 12 | E8: =1/D8 -> 0.083333333 | F8: =C8/D8 -> 3.1144808 | G8: =F8-H8 -> 0.54052973 | H8: =F8/(1+Assumptions!$B$7) -> 2.5739511 | I8: =H8*Assumptions!$B$21 -> 0.38609267 | J8: =F8*(Assumptions!$B$22+Assumptions!$B$24)+Assumptions!$B$23*E8 -> 0.089351912 | K8: =Assumptions!$B$19*I8+(1-Assumptions!$B$19)*J8 -> 0.26739636 | L8: =H8-K8 -> 2.3065547 | M8: =Assumptions!$B$33*Assumptions!$B$6*(1+Assumptions!$B$8) -> 0.457864 | N8: =Assumptions!$B$36 -> 0.02 | O8: =L8-M8-N8-$C$36 -> 1.814753 | P8: =IF(F8=0,0,O8/F8) -> 0.58268236 | Q8: =Assumptions!$B$34*Assumptions!$B$6*(1+Assumptions!$B$8) -> 3.1218 | R8: =L8-Q8-N8-$C$36 -> -0.84918296 | S8: =1-C8/(12*C7) -> 0.56202545
A10: Blended by each plan's annual share (Assumptions)
A11: Pro | B11: Blended | F11: =(1-Assumptions!$B$17)*F5+Assumptions!$B$17*F6 -> 3.1490499 | G11: =(1-Assumptions!$B$17)*G5+Assumptions!$B$17*G6 -> 0.54652932 | H11: =(1-Assumptions!$B$17)*H5+Assumptions!$B$17*H6 -> 2.6025206 | K11: =(1-Assumptions!$B$17)*K5+Assumptions!$B$17*K6 -> 0.29777183 | L11: =(1-Assumptions!$B$17)*L5+Assumptions!$B$17*L6 -> 2.3047488 | M11: =(1-Assumptions!$B$17)*M5+Assumptions!$B$17*M6 -> 0.280962 | N11: =(1-Assumptions!$B$17)*N5+Assumptions!$B$17*N6 -> 0.02 | O11: =(1-Assumptions!$B$17)*O5+Assumptions!$B$17*O6 -> 1.9976421 | P11: =IF(F11=0,0,O11/F11) -> 0.63436344 | Q11: =(1-Assumptions!$B$17)*Q5+Assumptions!$B$17*Q6 -> 2.49744 | R11: =(1-Assumptions!$B$17)*R5+Assumptions!$B$17*R6 -> -0.21883587
A12: Max | B12: Blended | F12: =(1-Assumptions!$B$18)*F7+Assumptions!$B$18*F8 -> 5.3126214 | G12: =(1-Assumptions!$B$18)*G7+Assumptions!$B$18*G8 -> 0.9220252 | H12: =(1-Assumptions!$B$18)*H7+Assumptions!$B$18*H8 -> 4.3905962 | K12: =(1-Assumptions!$B$18)*K7+Assumptions!$B$18*K8 -> 0.50065472 | L12: =(1-Assumptions!$B$18)*L7+Assumptions!$B$18*L8 -> 3.8899415 | M12: =(1-Assumptions!$B$18)*M7+Assumptions!$B$18*M8 -> 0.457864 | N12: =(1-Assumptions!$B$18)*N7+Assumptions!$B$18*N8 -> 0.02 | O12: =(1-Assumptions!$B$18)*O7+Assumptions!$B$18*O8 -> 3.4058055 | P12: =IF(F12=0,0,O12/F12) -> 0.64107815 | Q12: =(1-Assumptions!$B$18)*Q7+Assumptions!$B$18*Q8 -> 3.1218 | R12: =(1-Assumptions!$B$18)*R7+Assumptions!$B$18*R8 -> 0.74186949
A13: All payers | B13: Blended | F13: =IF((Assumptions!$B$15+Assumptions!$B$16)=0,0,Assumptions!$B$15/(Assumptions!$B$15+Assumptions!$B$16)*F11+(1-Assumptions!$B$15/(Assumptions!$B$15+Assumptions!$B$16))*F12) -> 3.5424265 | G13: =IF((Assumptions!$B$15+Assumptions!$B$16)=0,0,Assumptions!$B$15/(Assumptions!$B$15+Assumptions!$B$16)*G11+(1-Assumptions!$B$15/(Assumptions!$B$15+Assumptions!$B$16))*G12) -> 0.6148013 | H13: =IF((Assumptions!$B$15+Assumptions!$B$16)=0,0,Assumptions!$B$15/(Assumptions!$B$15+Assumptions!$B$16)*H11+(1-Assumptions!$B$15/(Assumptions!$B$15+Assumptions!$B$16))*H12) -> 2.9276252 | K13: =IF((Assumptions!$B$15+Assumptions!$B$16)=0,0,Assumptions!$B$15/(Assumptions!$B$15+Assumptions!$B$16)*K11+(1-Assumptions!$B$15/(Assumptions!$B$15+Assumptions!$B$16))*K12) -> 0.33465963 | L13: =IF((Assumptions!$B$15+Assumptions!$B$16)=0,0,Assumptions!$B$15/(Assumptions!$B$15+Assumptions!$B$16)*L11+(1-Assumptions!$B$15/(Assumptions!$B$15+Assumptions!$B$16))*L12) -> 2.5929656 | M13: =IF((Assumptions!$B$15+Assumptions!$B$16)=0,0,Assumptions!$B$15/(Assumptions!$B$15+Assumptions!$B$16)*M11+(1-Assumptions!$B$15/(Assumptions!$B$15+Assumptions!$B$16))*M12) -> 0.313126 | N13: =IF((Assumptions!$B$15+Assumptions!$B$16)=0,0,Assumptions!$B$15/(Assumptions!$B$15+Assumptions!$B$16)*N11+(1-Assumptions!$B$15/(Assumptions!$B$15+Assumptions!$B$16))*N12) -> 0.02 | O13: =IF((Assumptions!$B$15+Assumptions!$B$16)=0,0,Assumptions!$B$15/(Assumptions!$B$15+Assumptions!$B$16)*O11+(1-Assumptions!$B$15/(Assumptions!$B$15+Assumptions!$B$16))*O12) -> 2.2536718 | P13: =IF(F13=0,0,O13/F13) -> 0.63619437 | Q13: =IF((Assumptions!$B$15+Assumptions!$B$16)=0,0,Assumptions!$B$15/(Assumptions!$B$15+Assumptions!$B$16)*Q11+(1-Assumptions!$B$15/(Assumptions!$B$15+Assumptions!$B$16))*Q12) -> 2.61096 | R13: =IF((Assumptions!$B$15+Assumptions!$B$16)=0,0,Assumptions!$B$15/(Assumptions!$B$15+Assumptions!$B$16)*R11+(1-Assumptions!$B$15/(Assumptions!$B$15+Assumptions!$B$16))*R12) -> -0.044162172
A15: Where Pro annual is bought: what you keep (average regional price)
A16: Channel | C16: Price (€/yr) | D16: VAT (€) | E16: Commission / fees (€) | F16: You keep (€/yr) | G16: Share kept
A17: In-app (store) | C17: =C6 -> 31.14377 | D17: =C6-C6/(1+Assumptions!$B$7) -> 5.4051171 | E17: =C6/(1+Assumptions!$B$7)*Assumptions!$B$21 -> 3.8607979 | F17: =C17-D17-E17 -> 21.877855 | G17: =IF(C17=0,0,F17/C17) -> 0.70247934
A18: Web, VAT registered | C18: =C6 -> 31.14377 | D18: =C6-C6/(1+Assumptions!$B$7) -> 5.4051171 | E18: =C6*(Assumptions!$B$22+Assumptions!$B$24)+Assumptions!$B$23 -> 0.93516294 | F18: =C18-D18-E18 -> 24.80349 | G18: =IF(C18=0,0,F18/C18) -> 0.79641899
A19: Web, VAT-exempt (franchise) | C19: =C6 -> 31.14377 | D19: =0 -> 0 | E19: =C6*(Assumptions!$B$22+Assumptions!$B$24)+Assumptions!$B$23 -> 0.93516294 | F19: =C19-D19-E19 -> 30.208607 | G19: =IF(C19=0,0,F19/C19) -> 0.96997271
A21: Break-even (the result before social contributions and income tax)
A22: Stage | C22: Fixed costs (€/mo) | D22: Paying users needed | E22: Active users needed | F22: Contribution per active user (€/mo)
A23: Launch | C23: ='Fixed costs'!$I$24 -> 232.68245 | D23: =IF(ISNUMBER(E23),ROUNDUP(E23*(Assumptions!$B$15+Assumptions!$B$16),0),"never") -> 100 | E23: =IF(F23<=0,"never",ROUNDUP(C23/F23,0)) -> 1801 | F23: =(Assumptions!$B$15*$O$11+Assumptions!$B$16*$O$12)+(1-Assumptions!$B$15-Assumptions!$B$16)*(Assumptions!$B$54*Assumptions!$B$56*'Credit shop'!$G$22-$C$29)+Assumptions!$B$15*Assumptions!$B$55*Assumptions!$B$56*'Credit shop'!$G$22 -> 0.12922989
A24: Growth | C24: ='Fixed costs'!$J$24 -> 355.32145 | D24: =IF(ISNUMBER(E24),ROUNDUP(E24*(Assumptions!$B$15+Assumptions!$B$16),0),"never") -> 152 | E24: =IF(F24<=0,"never",ROUNDUP(C24/F24,0)) -> 2750 | F24: =(Assumptions!$B$15*$O$11+Assumptions!$B$16*$O$12)+(1-Assumptions!$B$15-Assumptions!$B$16)*(Assumptions!$B$54*Assumptions!$B$56*'Credit shop'!$G$22-$C$29)+Assumptions!$B$15*Assumptions!$B$55*Assumptions!$B$56*'Credit shop'!$G$22 -> 0.12922989
A25: Scale | C25: ='Fixed costs'!$K$24 -> 736.5767 | D25: =IF(ISNUMBER(E25),ROUNDUP(E25*(Assumptions!$B$15+Assumptions!$B$16),0),"never") -> 314 | E25: =IF(F25<=0,"never",ROUNDUP(C25/F25,0)) -> 5700 | F25: =(Assumptions!$B$15*$O$11+Assumptions!$B$16*$O$12)+(1-Assumptions!$B$15-Assumptions!$B$16)*(Assumptions!$B$54*Assumptions!$B$56*'Credit shop'!$G$22-$C$29)+Assumptions!$B$15*Assumptions!$B$55*Assumptions!$B$56*'Credit shop'!$G$22 -> 0.12922989
A27: Conservative: counts VAT on web sales. While the VAT exemption applies you keep more, so break-even comes sooner (see 'Projection'). Break-even counts every active user: the payers' margin, the credit packs, and what each free user costs, AI included.
